[0.000000] (-) TimerEvent: {}
[0.000375] (py_srvcli) JobQueued: {'identifier': 'py_srvcli', 'dependencies': OrderedDict()}
[0.000459] (py_srvcli) JobStarted: {'identifier': 'py_srvcli'}
[0.098014] (-) TimerEvent: {}
[0.198471] (-) TimerEvent: {}
[0.298895] (-) TimerEvent: {}
[0.399268] (-) TimerEvent: {}
[0.499660] (-) TimerEvent: {}
[0.600140] (-) TimerEvent: {}
[0.700655] (-) TimerEvent: {}
[0.801178] (-) TimerEvent: {}
[0.826819] (py_srvcli) StderrLine: {'line': b'Traceback (most recent call last):\n  File "/usr/lib/python3/dist-packages/colcon_parallel_executor/executor/parallel.py", line 67, in execute\n    loop.run_until_complete(future)\n  File "/usr/lib/python3.10/asyncio/base_events.py", line 633, in run_until_complete\n    self.run_forever()\n  File "/usr/lib/python3.10/asyncio/base_events.py", line 600, in run_forever\n    self._run_once()\n  File "/usr/lib/python3.10/asyncio/base_events.py", line 1860, in _run_once\n    event_list = self._selector.select(timeout)\n  File "/usr/lib/python3.10/selectors.py", line 469, in select\n    fd_event_list = self._selector.poll(timeout, max_ev)\nKeyboardInterrupt\n\nDuring handling of the above exception, another exception occurred:\n\nTraceback (most recent call last):\n  File "/usr/lib/python3/dist-packages/colcon_core/executor/__init__.py", line 91, in __call__\n    rc = await self.task(*args, **kwargs)\n  File "/usr/lib/python3/dist-packages/colcon_core/task/__init__.py", line 93, in __call__\n    return await task_method(*args, **kwargs)\n  File "/usr/lib/python3/dist-packages/colcon_ros/task/ament_python/build.py", line 105, in build\n    return await extension.build(additional_hooks=additional_hooks)\n  File "/usr/lib/python3/dist-packages/colcon_core/task/python/build.py", line 81, in build\n    available_commands = await self._get_available_commands(\n  File "/usr/lib/python3/dist-packages/colcon_core/task/python/build.py", line 171, in _get_available_commands\n    output = await check_output(\n  File "/usr/lib/python3/dist-packages/colcon_core/subprocess.py", line 128, in check_output\n    assert not rc, f\'Expected {args} to pass: {stderr_data}\'\nAssertionError: Expected [\'/usr/bin/python3\', \'setup.py\', \'--help-commands\'] to pass: Fatal Python error: init_import_site: Failed to import the site module\nPython runtime state: initialized\nTraceback (most recent call last):\n  File "/usr/lib/python3.10/site.py", line 636, in <module>\n    main()\n  File "/usr/lib/python3.10/site.py", line 623, in main\n    known_paths = addsitepackages(known_paths)\n  File "/usr/lib/python3.10/site.py", line 406, in addsitepackages\n    addsitedir(sitedir, known_paths)\n  File "/usr/lib/python3.10/site.py", line 232, in addsitedir\n    addpackage(sitedir, name, known_paths)\n  File "/usr/lib/python3.10/site.py", line 192, in addpackage\n    exec(line)\n  File "<string>", line 1, in <module>\n  File "<frozen importlib._bootstrap_external>", line 1439, in find_spec\n  File "<frozen importlib._bootstrap_external>", line 1411, in _get_spec\n  File "<frozen importlib._bootstrap_external>", line 1548, in find_spec\n  File "<frozen importlib._bootstrap_external>", line 1591, in _fill_cache\nKeyboardInterrupt\n\n'}
[0.828240] (py_srvcli) JobEnded: {'identifier': 'py_srvcli', 'rc': 'SIGINT'}
[0.837744] (-) EventReactorShutdown: {}
